Workbook

Sheet README
A1: Benin City Contraceptive Access Pilot: Data Collation & Visualization Template
A2: Collates data for the 11 learning questions and the headline indicator defined in the Data Strategy Table (v2).
A4: HOW TO USE
A5: 1. Settings | B5: Enter the pilot start date, currency label and confirm targets. Targets marked PLACEHOLDER were not in the strategy table and must be agreed.
A6: 2. Enter data | B6: Fill YELLOW cells (blue text) on the Headline and LQ1-LQ11 tabs at the frequency in the Register (weekly / bi-weekly / monthly / quarterly).
A7: 3. Read results | B7: The Dashboard scorecard and 14 charts update automatically. Grey cells are formulas: do not overwrite.
A8: 4. Clear examples | B8: Row 6 on each tab (and the first row of each LQ11 table and refusal-reason list) holds an illustrative EXAMPLE. Delete those values before real use.
A10: COLOUR LEGEND
A11: Yellow = input | B11: Input cell: type or select data here.
A12: Grey = formula | B12: Formula: calculated automatically.
A13: Teal header | B13: Column headers.
A15: TABS
A16: Dashboard | B16: Headline KPI cards, indicator scorecard (status vs target) and charts.
A17: Headline | B17: Monthly uptake conversion rate: unique clients engaged (App / Mobilizer / Walk-in) and unique clients receiving a method. Includes a data check against LQ7.
A18: LQ1_Experience … LQ11_Sustain | B18: One tab per learning question, with the indicators, source, owner and frequency from the strategy table at the top of each tab.
A19: Register | B19: Full indicator register (source, new/existing, responsible, frequency, start date, TOC level, quant/qual, feeds headline).
A20: Settings | B20: Pilot start date, targets and all dropdown lists (methods, channels, age groups, site categories, refusal reasons, kiosks, status).
A22: KEY ASSUMPTIONS & NOTES
A23: Month / week numbers | B23: Period dates are calculated from the pilot start date. Where a tab is a long list (LQ6, LQ7, LQ9) pick the Month # or Week # from the entry, and the date fills in.
A24: De-duplication | B24: Headline counts UNIQUE clients per month using the persistent digital client ID. Enter any cross-channel overlap in the Overlap column.
A25: Platform build cost | B25: LQ8 tracks platform build cost in a separate column and excludes it from unit cost, as specified in the strategy table.
A26: Start dates | B26: Indicators with later start dates (LQ3, LQ5, LQ8, LQ10) can simply be left blank in earlier months.
A27: Adding categories | B27: Insert a row inside the relevant list on Settings so dropdowns and summaries extend. Summary tables cover the current list lengths.
A28: LQ9 quarterly view | B28: Review the channel × age matrix (LQ9_SBC) quarterly to keep sample sizes stable, per the strategy table.
A29: Currency | B29: LQ8 costs use the currency label on Settings (NGN assumed). LQ11 co-financing is in $, as in the strategy table.

Sheet Dashboard
A1: Benin City Contraceptive Access Pilot: Learning & Headline Indicator Dashboard
A2: Updates automatically from the data-entry tabs. Example values are in row 6 of each tab: replace them before reading results.
A3: Latest monthly uptake conversion rate (HEADLINE) | D3: Headline target | G3: Unique clients engaged (all months) | J3: Unique clients receiving a method (all months) | M3: Cumulative conversion (received ÷ engaged)
A4: =IFERROR(LOOKUP(2,1/(Headline!$I$6:$I$17<>""),Headline!$I$6:$I$17),"") -> 0.39548023 | D4: =Settings!$B$7 -> 0.6 | G4: =SUM(Headline!$G$6:$G$17) -> 885 | J4: =SUM(Headline!$H$6:$H$17) -> 350 | M4: =IF(G4>0,J4/G4,"") -> 0.39548023
A7: Indicator scorecard (latest available value)
A8: # | B8: Learning question | E8: Key indicator shown | H8: Latest value | I8: Target / limit | J8: Status | K8: Data-entry tab | N8: Frequency
A9: H | B9: HEADLINE: method uptake conversion | E9: Uptake conversion rate (%) | H9: =IFERROR(LOOKUP(2,1/(Headline!$I$6:$I$17<>""),Headline!$I$6:$I$17),"") -> 0.39548023 | I9: =Settings!$B$7 -> 0.6 | J9: =IF(H9="","No data",IF(H9>=I9,"On track","Below target")) -> Below target | K9: Headline | N9: Monthly
A10: 1 | B10: Uptake drivers, barriers & client experience | E10: Avg client satisfaction (1-5) | H10: =IFERROR(LOOKUP(2,1/(LQ1_Experience!$F$6:$F$17<>""),LQ1_Experience!$F$6:$F$17),"") -> 4.3 | I10: =Settings!$B$8 -> 4 | J10: =IF(H10="","No data",IF(H10>=I10,"On track","Below target")) -> On track | K10: LQ1_Experience | N10: Monthly
A11: 2 | B11: Client-journey drop-off points | E11: Overall funnel conversion (uptake ÷ engagement) | H11: =IF(N(LQ2_Funnel!M6)>0,LQ2_Funnel!M9/LQ2_Funnel!M6,"") -> 0.35 | I11: Monitor | J11: =IF(H11="","No data","Monitor") -> Monitor | K11: LQ2_Funnel | N11: Weekly
A12: 3 | B12: User satisfaction | E12: Net Promoter Score | H12: =IFERROR(LOOKUP(2,1/(LQ3_Satisfaction!$G$6:$G$17<>""),LQ3_Satisfaction!$G$6:$G$17),"") -> 45 | I12: =Settings!$B$10 -> 40 | J12: =IF(H12="","No data",IF(H12>=I12,"On track","Below target")) -> On track | K12: LQ3_Satisfaction | N12: Monthly
A13: 4 | B13: Unassisted digital journey completion | E13: % unassisted journeys completed | H13: =IFERROR(LOOKUP(2,1/(LQ4_Unassisted!$G$6:$G$31<>""),LQ4_Unassisted!$G$6:$G$31),"") -> 0.5125 | I13: =Settings!$B$16 -> 0.5 | J13: =IF(H13="","No data",IF(H13>=I13,"On track","Below target")) -> On track | K13: LQ4_Unassisted | N13: Bi-weekly
A14: 5 | B14: Staff incentives & staffing model | E14: Monthly staff attrition rate | H14: =IFERROR(LOOKUP(2,1/(LQ5_Staffing!$F$6:$F$17<>""),LQ5_Staffing!$F$6:$F$17),"") -> 0.086956522 | I14: =Settings!$B$12 -> 0.05 | J14: =IF(H14="","No data",IF(H14<=I14,"On track","Above limit")) -> Above limit | K14: LQ5_Staffing | N14: Monthly
A15: 6 | B15: Kiosk location yield | E15: Best site category (foot traffic → registration) | H15: =IF(MAX(LQ6_Location!$O$6:$O$9)=0,"",INDEX(LQ6_Location!$K$6:$K$9,MATCH(MAX(LQ6_Location!$O$6:$O$9),LQ6_Location!$O$6:$O$9,0))) -> Market | I15: Monitor | J15: =IF(H15="","No data","Monitor") -> Monitor | K15: LQ6_Location | N15: Weekly
A16: 7 | B16: Method utilization & discontinuation | E16: Most-used method | H16: =IF(MAX(LQ7_Methods!$M$6:$M$12)=0,"",INDEX(LQ7_Methods!$L$6:$L$12,MATCH(MAX(LQ7_Methods!$M$6:$M$12),LQ7_Methods!$M$6:$M$12,0))) -> Injectable | I16: Monitor | J16: =IF(H16="","No data","Monitor") -> Monitor | K16: LQ7_Methods | N16: Monthly
A17: 8 | B17: Operational cost per client / kiosk | E17: Unit cost per client (see Settings for currency) | H17: =IFERROR(LOOKUP(2,1/(LQ8_Cost!$K$6:$K$17<>""),LQ8_Cost!$K$6:$K$17),"") -> 5084.7458 | I17: Monitor | J17: =IF(H17="","No data","Monitor") -> Monitor | K17: LQ8_Cost | N17: Monthly
A18: 9 | B18: SBC effectiveness by demographic | E18: Best channel (conversion rate) | H18: =IF(MAX(LQ9_SBC!$L$6:$L$12)=0,"",INDEX(LQ9_SBC!$I$6:$I$12,MATCH(MAX(LQ9_SBC!$L$6:$L$12),LQ9_SBC!$L$6:$L$12,0))) -> Mobilizer | I18: Monitor | J18: =IF(H18="","No data","Monitor") -> Monitor | K18: LQ9_SBC | N18: Monthly / Quarterly
A19: 10 | B19: DHIS2 / government data integration | E19: Data-sync success rate | H19: =IFERROR(LOOKUP(2,1/(LQ10_DHIS2!$E$6:$E$17<>""),LQ10_DHIS2!$E$6:$E$17),"") -> 0.94 | I19: =Settings!$B$13 -> 0.95 | J19: =IF(H19="","No data",IF(H19>=I19,"On track","Below target")) -> Below target | K19: LQ10_DHIS2 | N19: Monthly
A20: 11 | B20: Stakeholder ownership & sustainability | E20: % of co-financing target achieved | H20: =IF(N(LQ11_Sustain!J6)>0,LQ11_Sustain!J7/LQ11_Sustain!J6,"") -> 0.4 | I20: Monitor | J20: =IF(H20="","No data","Monitor") -> Monitor | K20: LQ11_Sustain | N20: Quarterly
A22: Charts

Sheet Headline
A1: Headline indicator: Monthly Contraceptive Method Uptake Conversion Rate (%)
A2: Rate = Unique clients receiving a method in month ÷ Unique clients engaged via App / Mobilizer / Walk-in in month × 100. Sources: App/CRM analytics (engagement); kiosk/PHC registers + inventory logs (uptake).
A3: Yellow cells (blue text) = enter data. Grey cells = formulas, do not overwrite. Row 6 holds an EXAMPLE entry: overwrite or clear it before real use. Count each client once per month using the persistent digital client ID.
A5: Month # | B5: Month | C5: Unique clients engaged: App | D5: Unique clients engaged: Mobilizer | E5: Unique clients engaged: Walk-in | F5: Overlap: clients counted in >1 channel | G5: Unique clients engaged (de-duplicated) | H5: Unique clients receiving a method | I5: HEADLINE: Uptake conversion rate | J5: Target | K5: Methods issued (from LQ7_Methods) | L5: Data check
A6: 1 | B6: =EDATE(Settings!$B$4,$A6-1) -> 46327 | C6: 420 | D6: 310 | E6: 180 | F6: 25 | G6: =IF(COUNT(C6:E6)=0,"",SUM(C6:E6)-N(F6)) -> 885 | H6: 350 | I6: =IF(AND(ISNUMBER(G6),N(G6)>0,ISNUMBER(H6)),H6/G6,"") -> 0.39548023 | J6: =Settings!$B$7 -> 0.6 | K6: =SUMIFS(LQ7_Methods!$D$6:$D$105,LQ7_Methods!$A$6:$A$105,$A6) -> 120 | L6: =IF(H6="","",IF(N(H6)>N(G6),"CHECK: uptake exceeds engaged",IF(AND(K6>0,H6>K6),"CHECK: unique clients exceed methods issued","OK"))) -> CHECK: unique clients exceed methods issued
A7: 2 | B7: =EDATE(Settings!$B$4,$A7-1) -> 46357 | G7: =IF(COUNT(C7:E7)=0,"",SUM(C7:E7)-N(F7)) | I7: =IF(AND(ISNUMBER(G7),N(G7)>0,ISNUMBER(H7)),H7/G7,"") | J7: =Settings!$B$7 -> 0.6 | K7: =SUMIFS(LQ7_Methods!$D$6:$D$105,LQ7_Methods!$A$6:$A$105,$A7) -> 0 | L7: =IF(H7="","",IF(N(H7)>N(G7),"CHECK: uptake exceeds engaged",IF(AND(K7>0,H7>K7),"CHECK: unique clients exceed methods issued","OK")))
A8: 3 | B8: =EDATE(Settings!$B$4,$A8-1) -> 46388 | G8: =IF(COUNT(C8:E8)=0,"",SUM(C8:E8)-N(F8)) | I8: =IF(AND(ISNUMBER(G8),N(G8)>0,ISNUMBER(H8)),H8/G8,"") | J8: =Settings!$B$7 -> 0.6 | K8: =SUMIFS(LQ7_Methods!$D$6:$D$105,LQ7_Methods!$A$6:$A$105,$A8) -> 0 | L8: =IF(H8="","",IF(N(H8)>N(G8),"CHECK: uptake exceeds engaged",IF(AND(K8>0,H8>K8),"CHECK: unique clients exceed methods issued","OK")))
A9: 4 | B9: =EDATE(Settings!$B$4,$A9-1) -> 46419 | G9: =IF(COUNT(C9:E9)=0,"",SUM(C9:E9)-N(F9)) | I9: =IF(AND(ISNUMBER(G9),N(G9)>0,ISNUMBER(H9)),H9/G9,"") | J9: =Settings!$B$7 -> 0.6 | K9: =SUMIFS(LQ7_Methods!$D$6:$D$105,LQ7_Methods!$A$6:$A$105,$A9) -> 0 | L9: =IF(H9="","",IF(N(H9)>N(G9),"CHECK: uptake exceeds engaged",IF(AND(K9>0,H9>K9),"CHECK: unique clients exceed methods issued","OK")))
A10: 5 | B10: =EDATE(Settings!$B$4,$A10-1) -> 46447 | G10: =IF(COUNT(C10:E10)=0,"",SUM(C10:E10)-N(F10)) | I10: =IF(AND(ISNUMBER(G10),N(G10)>0,ISNUMBER(H10)),H10/G10,"") | J10: =Settings!$B$7 -> 0.6 | K10: =SUMIFS(LQ7_Methods!$D$6:$D$105,LQ7_Methods!$A$6:$A$105,$A10) -> 0 | L10: =IF(H10="","",IF(N(H10)>N(G10),"CHECK: uptake exceeds engaged",IF(AND(K10>0,H10>K10),"CHECK: unique clients exceed methods issued","OK")))
A11: 6 | B11: =EDATE(Settings!$B$4,$A11-1) -> 46478 | G11: =IF(COUNT(C11:E11)=0,"",SUM(C11:E11)-N(F11)) | I11: =IF(AND(ISNUMBER(G11),N(G11)>0,ISNUMBER(H11)),H11/G11,"") | J11: =Settings!$B$7 -> 0.6 | K11: =SUMIFS(LQ7_Methods!$D$6:$D$105,LQ7_Methods!$A$6:$A$105,$A11) -> 0 | L11: =IF(H11="","",IF(N(H11)>N(G11),"CHECK: uptake exceeds engaged",IF(AND(K11>0,H11>K11),"CHECK: unique clients exceed methods issued","OK")))
A12: 7 | B12: =EDATE(Settings!$B$4,$A12-1) -> 46508 | G12: =IF(COUNT(C12:E12)=0,"",SUM(C12:E12)-N(F12)) | I12: =IF(AND(ISNUMBER(G12),N(G12)>0,ISNUMBER(H12)),H12/G12,"") | J12: =Settings!$B$7 -> 0.6 | K12: =SUMIFS(LQ7_Methods!$D$6:$D$105,LQ7_Methods!$A$6:$A$105,$A12) -> 0 | L12: =IF(H12="","",IF(N(H12)>N(G12),"CHECK: uptake exceeds engaged",IF(AND(K12>0,H12>K12),"CHECK: unique clients exceed methods issued","OK")))
A13: 8 | B13: =EDATE(Settings!$B$4,$A13-1) -> 46539 | G13: =IF(COUNT(C13:E13)=0,"",SUM(C13:E13)-N(F13)) | I13: =IF(AND(ISNUMBER(G13),N(G13)>0,ISNUMBER(H13)),H13/G13,"") | J13: =Settings!$B$7 -> 0.6 | K13: =SUMIFS(LQ7_Methods!$D$6:$D$105,LQ7_Methods!$A$6:$A$105,$A13) -> 0 | L13: =IF(H13="","",IF(N(H13)>N(G13),"CHECK: uptake exceeds engaged",IF(AND(K13>0,H13>K13),"CHECK: unique clients exceed methods issued","OK")))
A14: 9 | B14: =EDATE(Settings!$B$4,$A14-1) -> 46569 | G14: =IF(COUNT(C14:E14)=0,"",SUM(C14:E14)-N(F14)) | I14: =IF(AND(ISNUMBER(G14),N(G14)>0,ISNUMBER(H14)),H14/G14,"") | J14: =Settings!$B$7 -> 0.6 | K14: =SUMIFS(LQ7_Methods!$D$6:$D$105,LQ7_Methods!$A$6:$A$105,$A14) -> 0 | L14: =IF(H14="","",IF(N(H14)>N(G14),"CHECK: uptake exceeds engaged",IF(AND(K14>0,H14>K14),"CHECK: unique clients exceed methods issued","OK")))
A15: 10 | B15: =EDATE(Settings!$B$4,$A15-1) -> 46600 | G15: =IF(COUNT(C15:E15)=0,"",SUM(C15:E15)-N(F15)) | I15: =IF(AND(ISNUMBER(G15),N(G15)>0,ISNUMBER(H15)),H15/G15,"") | J15: =Settings!$B$7 -> 0.6 | K15: =SUMIFS(LQ7_Methods!$D$6:$D$105,LQ7_Methods!$A$6:$A$105,$A15) -> 0 | L15: =IF(H15="","",IF(N(H15)>N(G15),"CHECK: uptake exceeds engaged",IF(AND(K15>0,H15>K15),"CHECK: unique clients exceed methods issued","OK")))
A16: 11 | B16: =EDATE(Settings!$B$4,$A16-1) -> 46631 | G16: =IF(COUNT(C16:E16)=0,"",SUM(C16:E16)-N(F16)) | I16: =IF(AND(ISNUMBER(G16),N(G16)>0,ISNUMBER(H16)),H16/G16,"") | J16: =Settings!$B$7 -> 0.6 | K16: =SUMIFS(LQ7_Methods!$D$6:$D$105,LQ7_Methods!$A$6:$A$105,$A16) -> 0 | L16: =IF(H16="","",IF(N(H16)>N(G16),"CHECK: uptake exceeds engaged",IF(AND(K16>0,H16>K16),"CHECK: unique clients exceed methods issued","OK")))
A17: 12 | B17: =EDATE(Settings!$B$4,$A17-1) -> 46661 | G17: =IF(COUNT(C17:E17)=0,"",SUM(C17:E17)-N(F17)) | I17: =IF(AND(ISNUMBER(G17),N(G17)>0,ISNUMBER(H17)),H17/G17,"") | J17: =Settings!$B$7 -> 0.6 | K17: =SUMIFS(LQ7_Methods!$D$6:$D$105,LQ7_Methods!$A$6:$A$105,$A17) -> 0 | L17: =IF(H17="","",IF(N(H17)>N(G17),"CHECK: uptake exceeds engaged",IF(AND(K17>0,H17>K17),"CHECK: unique clients exceed methods issued","OK")))

Sheet LQ1_Experience
A1: LQ1: Uptake drivers, barriers and client experience
A2: Indicators: client satisfaction score (post-visit, 1-5); barrier-reporting rate (% exit surveys citing ≥1 barrier); provider counseling-quality score (digital observation rubric). Responsible: City team & Implementation partner. Monthly.
A3: Yellow cells (blue text) = enter data. Grey cells = formulas, do not overwrite. Row 6 holds an EXAMPLE entry: overwrite or clear it before real use.
A5: Month # | B5: Month | C5: Exit surveys completed | D5: Surveys citing ≥1 barrier | E5: Barrier-reporting rate | F5: Avg client satisfaction (1-5) | G5: Observations completed | H5: Avg counseling-quality score (1-5) | I5: Key drivers / barriers (qualitative summary)
A6: 1 | B6: =EDATE(Settings!$B$4,$A6-1) -> 46327 | C6: 120 | D6: 38 | E6: =IF(N(C6)>0,D6/C6,"") -> 0.31666667 | F6: 4.3 | G6: 8 | H6: 3.9 | I6: Fear of side effects most cited; short waiting times valued.
A7: 2 | B7: =EDATE(Settings!$B$4,$A7-1) -> 46357 | E7: =IF(N(C7)>0,D7/C7,"")
A8: 3 | B8: =EDATE(Settings!$B$4,$A8-1) -> 46388 | E8: =IF(N(C8)>0,D8/C8,"")
A9: 4 | B9: =EDATE(Settings!$B$4,$A9-1) -> 46419 | E9: =IF(N(C9)>0,D9/C9,"")
A10: 5 | B10: =EDATE(Settings!$B$4,$A10-1) -> 46447 | E10: =IF(N(C10)>0,D10/C10,"")
A11: 6 | B11: =EDATE(Settings!$B$4,$A11-1) -> 46478 | E11: =IF(N(C11)>0,D11/C11,"")
A12: 7 | B12: =EDATE(Settings!$B$4,$A12-1) -> 46508 | E12: =IF(N(C12)>0,D12/C12,"")
A13: 8 | B13: =EDATE(Settings!$B$4,$A13-1) -> 46539 | E13: =IF(N(C13)>0,D13/C13,"")
A14: 9 | B14: =EDATE(Settings!$B$4,$A14-1) -> 46569 | E14: =IF(N(C14)>0,D14/C14,"")
A15: 10 | B15: =EDATE(Settings!$B$4,$A15-1) -> 46600 | E15: =IF(N(C15)>0,D15/C15,"")
A16: 11 | B16: =EDATE(Settings!$B$4,$A16-1) -> 46631 | E16: =IF(N(C16)>0,D16/C16,"")
A17: 12 | B17: =EDATE(Settings!$B$4,$A17-1) -> 46661 | E17: =IF(N(C17)>0,D17/C17,"")

Sheet LQ2_Funnel
A1: LQ2: Client-journey drop-off points (weekly funnel)
A2: Indicator: stage-by-stage conversion / drop-off (app engagement → registration → kiosk/PHC referral → method uptake) under one persistent client ID. Responsible: Implementation partner. Weekly.
A3: Yellow cells (blue text) = enter data. Grey cells = formulas, do not overwrite. Row 6 holds an EXAMPLE entry: overwrite or clear it before real use.
L4: Funnel summary (cumulative)
A5: Week # | B5: Week start | C5: 1. App engagement | D5: 2. Registration | E5: 3. Kiosk/PHC referral (check-in) | F5: 4. Method uptake | G5: Registration ÷ engagement | H5: Referral ÷ registration | I5: Uptake ÷ referral | J5: Overall: uptake ÷ engagement | L5: Stage | M5: Total clients | N5: % of stage 1 | O5: Step conversion | P5: Step drop-off
A6: 1 | B6: =Settings!$B$4+7*($A6-1) -> 46327 | C6: 600 | D6: 410 | E6: 320 | F6: 210 | G6: =IF(N(C6)>0,D6/C6,"") -> 0.68333333 | H6: =IF(N(D6)>0,E6/D6,"") -> 0.7804878 | I6: =IF(N(E6)>0,F6/E6,"") -> 0.65625 | J6: =IF(N(C6)>0,F6/C6,"") -> 0.35 | L6: 1. App engagement | M6: =SUM(C6:C57) -> 600 | N6: =IF($M$6>0,M6/$M$6,"") -> 1
A7: 2 | B7: =Settings!$B$4+7*($A7-1) -> 46334 | G7: =IF(N(C7)>0,D7/C7,"") | H7: =IF(N(D7)>0,E7/D7,"") | I7: =IF(N(E7)>0,F7/E7,"") | J7: =IF(N(C7)>0,F7/C7,"") | L7: 2. Registration | M7: =SUM(D6:D57) -> 410 | N7: =IF($M$6>0,M7/$M$6,"") -> 0.68333333 | O7: =IF(N(M6)>0,M7/M6,"") -> 0.68333333 | P7: =IF(ISNUMBER(O7),1-O7,"") -> 0.31666667
A8: 3 | B8: =Settings!$B$4+7*($A8-1) -> 46341 | G8: =IF(N(C8)>0,D8/C8,"") | H8: =IF(N(D8)>0,E8/D8,"") | I8: =IF(N(E8)>0,F8/E8,"") | J8: =IF(N(C8)>0,F8/C8,"") | L8: 3. Kiosk/PHC referral | M8: =SUM(E6:E57) -> 320 | N8: =IF($M$6>0,M8/$M$6,"") -> 0.53333333 | O8: =IF(N(M7)>0,M8/M7,"") -> 0.7804878 | P8: =IF(ISNUMBER(O8),1-O8,"") -> 0.2195122
A9: 4 | B9: =Settings!$B$4+7*($A9-1) -> 46348 | G9: =IF(N(C9)>0,D9/C9,"") | H9: =IF(N(D9)>0,E9/D9,"") | I9: =IF(N(E9)>0,F9/E9,"") | J9: =IF(N(C9)>0,F9/C9,"") | L9: 4. Method uptake | M9: =SUM(F6:F57) -> 210 | N9: =IF($M$6>0,M9/$M$6,"") -> 0.35 | O9: =IF(N(M8)>0,M9/M8,"") -> 0.65625 | P9: =IF(ISNUMBER(O9),1-O9,"") -> 0.34375
A10: 5 | B10: =Settings!$B$4+7*($A10-1) -> 46355 | G10: =IF(N(C10)>0,D10/C10,"") | H10: =IF(N(D10)>0,E10/D10,"") | I10: =IF(N(E10)>0,F10/E10,"") | J10: =IF(N(C10)>0,F10/C10,"")
A11: 6 | B11: =Settings!$B$4+7*($A11-1) -> 46362 | G11: =IF(N(C11)>0,D11/C11,"") | H11: =IF(N(D11)>0,E11/D11,"") | I11: =IF(N(E11)>0,F11/E11,"") | J11: =IF(N(C11)>0,F11/C11,"")
A12: 7 | B12: =Settings!$B$4+7*($A12-1) -> 46369 | G12: =IF(N(C12)>0,D12/C12,"") | H12: =IF(N(D12)>0,E12/D12,"") | I12: =IF(N(E12)>0,F12/E12,"") | J12: =IF(N(C12)>0,F12/C12,"")
A13: 8 | B13: =Settings!$B$4+7*($A13-1) -> 46376 | G13: =IF(N(C13)>0,D13/C13,"") | H13: =IF(N(D13)>0,E13/D13,"") | I13: =IF(N(E13)>0,F13/E13,"") | J13: =IF(N(C13)>0,F13/C13,"")
A14: 9 | B14: =Settings!$B$4+7*($A14-1) -> 46383 | G14: =IF(N(C14)>0,D14/C14,"") | H14: =IF(N(D14)>0,E14/D14,"") | I14: =IF(N(E14)>0,F14/E14,"") | J14: =IF(N(C14)>0,F14/C14,"")
A15: 10 | B15: =Settings!$B$4+7*($A15-1) -> 46390 | G15: =IF(N(C15)>0,D15/C15,"") | H15: =IF(N(D15)>0,E15/D15,"") | I15: =IF(N(E15)>0,F15/E15,"") | J15: =IF(N(C15)>0,F15/C15,"")
A16: 11 | B16: =Settings!$B$4+7*($A16-1) -> 46397 | G16: =IF(N(C16)>0,D16/C16,"") | H16: =IF(N(D16)>0,E16/D16,"") | I16: =IF(N(E16)>0,F16/E16,"") | J16: =IF(N(C16)>0,F16/C16,"")
A17: 12 | B17: =Settings!$B$4+7*($A17-1) -> 46404 | G17: =IF(N(C17)>0,D17/C17,"") | H17: =IF(N(D17)>0,E17/D17,"") | I17: =IF(N(E17)>0,F17/E17,"") | J17: =IF(N(C17)>0,F17/C17,"")
A18: 13 | B18: =Settings!$B$4+7*($A18-1) -> 46411 | G18: =IF(N(C18)>0,D18/C18,"") | H18: =IF(N(D18)>0,E18/D18,"") | I18: =IF(N(E18)>0,F18/E18,"") | J18: =IF(N(C18)>0,F18/C18,"")
A19: 14 | B19: =Settings!$B$4+7*($A19-1) -> 46418 | G19: =IF(N(C19)>0,D19/C19,"") | H19: =IF(N(D19)>0,E19/D19,"") | I19: =IF(N(E19)>0,F19/E19,"") | J19: =IF(N(C19)>0,F19/C19,"")
A20: 15 | B20: =Settings!$B$4+7*($A20-1) -> 46425 | G20: =IF(N(C20)>0,D20/C20,"") | H20: =IF(N(D20)>0,E20/D20,"") | I20: =IF(N(E20)>0,F20/E20,"") | J20: =IF(N(C20)>0,F20/C20,"")
A21: 16 | B21: =Settings!$B$4+7*($A21-1) -> 46432 | G21: =IF(N(C21)>0,D21/C21,"") | H21: =IF(N(D21)>0,E21/D21,"") | I21: =IF(N(E21)>0,F21/E21,"") | J21: =IF(N(C21)>0,F21/C21,"")
... A57: 52 | B57: =Settings!$B$4+7*($A57-1) -> 46684 | G57: =IF(N(C57)>0,D57/C57,"") | H57: =IF(N(D57)>0,E57/D57,"") | I57: =IF(N(E57)>0,F57/E57,"") | J57: =IF(N(C57)>0,F57/C57,"")

Sheet LQ3_Satisfaction
A1: LQ3: User satisfaction (NPS) and client ambassadors
A2: Indicators: monthly Net Promoter Score; client ambassadors = clients whose unique digital referral code is used ≥2 times in a month (reviewed quarterly). Responsible: City team.
A3: Yellow cells (blue text) = enter data. Grey cells = formulas, do not overwrite. Row 6 holds an EXAMPLE entry: overwrite or clear it before real use.
J4: Ambassadors by quarter
A5: Month # | B5: Month | C5: Promoters (9-10) | D5: Passives (7-8) | E5: Detractors (0-6) | F5: Responses | G5: NPS (-100 to 100) | H5: New ambassadors this month | J5: Quarter | K5: Ambassadors
A6: 1 | B6: =EDATE(Settings!$B$4,$A6-1) -> 46327 | C6: 60 | D6: 25 | E6: 15 | F6: =IF(COUNT(C6:E6)=0,"",SUM(C6:E6)) -> 100 | G6: =IF(AND(ISNUMBER(F6),N(F6)>0),(C6-E6)/F6*100,"") -> 45 | H6: 6 | J6: Q1 (months 1-3) | K6: =SUM(H6:H8) -> 6
A7: 2 | B7: =EDATE(Settings!$B$4,$A7-1) -> 46357 | F7: =IF(COUNT(C7:E7)=0,"",SUM(C7:E7)) | G7: =IF(AND(ISNUMBER(F7),N(F7)>0),(C7-E7)/F7*100,"") | J7: Q2 (months 4-6) | K7: =SUM(H9:H11) -> 0
A8: 3 | B8: =EDATE(Settings!$B$4,$A8-1) -> 46388 | F8: =IF(COUNT(C8:E8)=0,"",SUM(C8:E8)) | G8: =IF(AND(ISNUMBER(F8),N(F8)>0),(C8-E8)/F8*100,"") | J8: Q3 (months 7-9) | K8: =SUM(H12:H14) -> 0
A9: 4 | B9: =EDATE(Settings!$B$4,$A9-1) -> 46419 | F9: =IF(COUNT(C9:E9)=0,"",SUM(C9:E9)) | G9: =IF(AND(ISNUMBER(F9),N(F9)>0),(C9-E9)/F9*100,"") | J9: Q4 (months 10-12) | K9: =SUM(H15:H17) -> 0
A10: 5 | B10: =EDATE(Settings!$B$4,$A10-1) -> 46447 | F10: =IF(COUNT(C10:E10)=0,"",SUM(C10:E10)) | G10: =IF(AND(ISNUMBER(F10),N(F10)>0),(C10-E10)/F10*100,"")
A11: 6 | B11: =EDATE(Settings!$B$4,$A11-1) -> 46478 | F11: =IF(COUNT(C11:E11)=0,"",SUM(C11:E11)) | G11: =IF(AND(ISNUMBER(F11),N(F11)>0),(C11-E11)/F11*100,"")
A12: 7 | B12: =EDATE(Settings!$B$4,$A12-1) -> 46508 | F12: =IF(COUNT(C12:E12)=0,"",SUM(C12:E12)) | G12: =IF(AND(ISNUMBER(F12),N(F12)>0),(C12-E12)/F12*100,"")
A13: 8 | B13: =EDATE(Settings!$B$4,$A13-1) -> 46539 | F13: =IF(COUNT(C13:E13)=0,"",SUM(C13:E13)) | G13: =IF(AND(ISNUMBER(F13),N(F13)>0),(C13-E13)/F13*100,"")
A14: 9 | B14: =EDATE(Settings!$B$4,$A14-1) -> 46569 | F14: =IF(COUNT(C14:E14)=0,"",SUM(C14:E14)) | G14: =IF(AND(ISNUMBER(F14),N(F14)>0),(C14-E14)/F14*100,"")
A15: 10 | B15: =EDATE(Settings!$B$4,$A15-1) -> 46600 | F15: =IF(COUNT(C15:E15)=0,"",SUM(C15:E15)) | G15: =IF(AND(ISNUMBER(F15),N(F15)>0),(C15-E15)/F15*100,"")
A16: 11 | B16: =EDATE(Settings!$B$4,$A16-1) -> 46631 | F16: =IF(COUNT(C16:E16)=0,"",SUM(C16:E16)) | G16: =IF(AND(ISNUMBER(F16),N(F16)>0),(C16-E16)/F16*100,"")
A17: 12 | B17: =EDATE(Settings!$B$4,$A17-1) -> 46661 | F17: =IF(COUNT(C17:E17)=0,"",SUM(C17:E17)) | G17: =IF(AND(ISNUMBER(F17),N(F17)>0),(C17-E17)/F17*100,"")

Sheet LQ4_Unassisted
A1: LQ4: Unassisted digital journey completion (bi-weekly)
A2: Indicators: % of unassisted journeys completed; conversion-rate gap between self-navigating and mobilizer-assisted cohorts (opt-in comparison). Responsible: Implementation partner.
A3: Yellow cells (blue text) = enter data. Grey cells = formulas, do not overwrite. Row 6 holds an EXAMPLE entry: overwrite or clear it before real use.
A5: Period # | B5: Period start | C5: Self-navigating: journeys started | D5: Self-navigating: journeys completed | E5: Mobilizer-assisted: journeys started | F5: Mobilizer-assisted: journeys completed | G5: % unassisted completed | H5: % assisted completed | I5: Gap (unassisted − assisted)
A6: 1 | B6: =Settings!$B$4+14*($A6-1) -> 46327 | C6: 80 | D6: 41 | E6: 150 | F6: 118 | G6: =IF(N(C6)>0,D6/C6,"") -> 0.5125 | H6: =IF(N(E6)>0,F6/E6,"") -> 0.78666667 | I6: =IF(AND(ISNUMBER(G6),ISNUMBER(H6)),G6-H6,"") -> -0.27416667
A7: 2 | B7: =Settings!$B$4+14*($A7-1) -> 46341 | G7: =IF(N(C7)>0,D7/C7,"") | H7: =IF(N(E7)>0,F7/E7,"") | I7: =IF(AND(ISNUMBER(G7),ISNUMBER(H7)),G7-H7,"")
A8: 3 | B8: =Settings!$B$4+14*($A8-1) -> 46355 | G8: =IF(N(C8)>0,D8/C8,"") | H8: =IF(N(E8)>0,F8/E8,"") | I8: =IF(AND(ISNUMBER(G8),ISNUMBER(H8)),G8-H8,"")
A9: 4 | B9: =Settings!$B$4+14*($A9-1) -> 46369 | G9: =IF(N(C9)>0,D9/C9,"") | H9: =IF(N(E9)>0,F9/E9,"") | I9: =IF(AND(ISNUMBER(G9),ISNUMBER(H9)),G9-H9,"")
A10: 5 | B10: =Settings!$B$4+14*($A10-1) -> 46383 | G10: =IF(N(C10)>0,D10/C10,"") | H10: =IF(N(E10)>0,F10/E10,"") | I10: =IF(AND(ISNUMBER(G10),ISNUMBER(H10)),G10-H10,"")
A11: 6 | B11: =Settings!$B$4+14*($A11-1) -> 46397 | G11: =IF(N(C11)>0,D11/C11,"") | H11: =IF(N(E11)>0,F11/E11,"") | I11: =IF(AND(ISNUMBER(G11),ISNUMBER(H11)),G11-H11,"")
A12: 7 | B12: =Settings!$B$4+14*($A12-1) -> 46411 | G12: =IF(N(C12)>0,D12/C12,"") | H12: =IF(N(E12)>0,F12/E12,"") | I12: =IF(AND(ISNUMBER(G12),ISNUMBER(H12)),G12-H12,"")
A13: 8 | B13: =Settings!$B$4+14*($A13-1) -> 46425 | G13: =IF(N(C13)>0,D13/C13,"") | H13: =IF(N(E13)>0,F13/E13,"") | I13: =IF(AND(ISNUMBER(G13),ISNUMBER(H13)),G13-H13,"")
A14: 9 | B14: =Settings!$B$4+14*($A14-1) -> 46439 | G14: =IF(N(C14)>0,D14/C14,"") | H14: =IF(N(E14)>0,F14/E14,"") | I14: =IF(AND(ISNUMBER(G14),ISNUMBER(H14)),G14-H14,"")
A15: 10 | B15: =Settings!$B$4+14*($A15-1) -> 46453 | G15: =IF(N(C15)>0,D15/C15,"") | H15: =IF(N(E15)>0,F15/E15,"") | I15: =IF(AND(ISNUMBER(G15),ISNUMBER(H15)),G15-H15,"")
A16: 11 | B16: =Settings!$B$4+14*($A16-1) -> 46467 | G16: =IF(N(C16)>0,D16/C16,"") | H16: =IF(N(E16)>0,F16/E16,"") | I16: =IF(AND(ISNUMBER(G16),ISNUMBER(H16)),G16-H16,"")
A17: 12 | B17: =Settings!$B$4+14*($A17-1) -> 46481 | G17: =IF(N(C17)>0,D17/C17,"") | H17: =IF(N(E17)>0,F17/E17,"") | I17: =IF(AND(ISNUMBER(G17),ISNUMBER(H17)),G17-H17,"")
A18: 13 | B18: =Settings!$B$4+14*($A18-1) -> 46495 | G18: =IF(N(C18)>0,D18/C18,"") | H18: =IF(N(E18)>0,F18/E18,"") | I18: =IF(AND(ISNUMBER(G18),ISNUMBER(H18)),G18-H18,"")
... A31: 26 | B31: =Settings!$B$4+14*($A31-1) -> 46677 | G31: =IF(N(C31)>0,D31/C31,"") | H31: =IF(N(E31)>0,F31/E31,"") | I31: =IF(AND(ISNUMBER(G31),ISNUMBER(H31)),G31-H31,"")

Sheet LQ5_Staffing
A1: LQ5: Staff incentives and staffing model
A2: Indicators: monthly staff attrition rate; client-to-staff ratio; staff satisfaction (in-app pulse survey). Responsible: City team. Monthly / quarterly. Starts 2 months post-launch.
A3: Yellow cells (blue text) = enter data. Grey cells = formulas, do not overwrite. Row 6 holds an EXAMPLE entry: overwrite or clear it before real use.
A5: Month # | B5: Month | C5: Staff at start of month | D5: Staff leavers in month | E5: Staff at end of month | F5: Attrition rate | G5: Kiosks operating | H5: Clients served | I5: Client-to-staff ratio | J5: Staff per kiosk | K5: Avg staff satisfaction (1-5) | L5: Pulse survey responses | M5: Incentive / staffing model notes
A6: 1 | B6: =EDATE(Settings!$B$4,$A6-1) -> 46327 | C6: 12 | D6: 1 | E6: 11 | F6: =IF(COUNT(C6,E6)=2,IF(AVERAGE(C6,E6)>0,N(D6)/AVERAGE(C6,E6),""),"") -> 0.086956522 | G6: 4 | H6: 885 | I6: =IF(COUNT(C6,E6)=2,IF(AVERAGE(C6,E6)>0,H6/AVERAGE(C6,E6),""),"") -> 76.956522 | J6: =IF(COUNT(C6,E6)=2,IF(N(G6)>0,AVERAGE(C6,E6)/G6,""),"") -> 2.875 | K6: 4.1 | L6: 10 | M6: Performance bonus piloted at K02.
A7: 2 | B7: =EDATE(Settings!$B$4,$A7-1) -> 46357 | F7: =IF(COUNT(C7,E7)=2,IF(AVERAGE(C7,E7)>0,N(D7)/AVERAGE(C7,E7),""),"") | I7: =IF(COUNT(C7,E7)=2,IF(AVERAGE(C7,E7)>0,H7/AVERAGE(C7,E7),""),"") | J7: =IF(COUNT(C7,E7)=2,IF(N(G7)>0,AVERAGE(C7,E7)/G7,""),"")
A8: 3 | B8: =EDATE(Settings!$B$4,$A8-1) -> 46388 | F8: =IF(COUNT(C8,E8)=2,IF(AVERAGE(C8,E8)>0,N(D8)/AVERAGE(C8,E8),""),"") | I8: =IF(COUNT(C8,E8)=2,IF(AVERAGE(C8,E8)>0,H8/AVERAGE(C8,E8),""),"") | J8: =IF(COUNT(C8,E8)=2,IF(N(G8)>0,AVERAGE(C8,E8)/G8,""),"")
A9: 4 | B9: =EDATE(Settings!$B$4,$A9-1) -> 46419 | F9: =IF(COUNT(C9,E9)=2,IF(AVERAGE(C9,E9)>0,N(D9)/AVERAGE(C9,E9),""),"") | I9: =IF(COUNT(C9,E9)=2,IF(AVERAGE(C9,E9)>0,H9/AVERAGE(C9,E9),""),"") | J9: =IF(COUNT(C9,E9)=2,IF(N(G9)>0,AVERAGE(C9,E9)/G9,""),"")
A10: 5 | B10: =EDATE(Settings!$B$4,$A10-1) -> 46447 | F10: =IF(COUNT(C10,E10)=2,IF(AVERAGE(C10,E10)>0,N(D10)/AVERAGE(C10,E10),""),"") | I10: =IF(COUNT(C10,E10)=2,IF(AVERAGE(C10,E10)>0,H10/AVERAGE(C10,E10),""),"") | J10: =IF(COUNT(C10,E10)=2,IF(N(G10)>0,AVERAGE(C10,E10)/G10,""),"")
A11: 6 | B11: =EDATE(Settings!$B$4,$A11-1) -> 46478 | F11: =IF(COUNT(C11,E11)=2,IF(AVERAGE(C11,E11)>0,N(D11)/AVERAGE(C11,E11),""),"") | I11: =IF(COUNT(C11,E11)=2,IF(AVERAGE(C11,E11)>0,H11/AVERAGE(C11,E11),""),"") | J11: =IF(COUNT(C11,E11)=2,IF(N(G11)>0,AVERAGE(C11,E11)/G11,""),"")
A12: 7 | B12: =EDATE(Settings!$B$4,$A12-1) -> 46508 | F12: =IF(COUNT(C12,E12)=2,IF(AVERAGE(C12,E12)>0,N(D12)/AVERAGE(C12,E12),""),"") | I12: =IF(COUNT(C12,E12)=2,IF(AVERAGE(C12,E12)>0,H12/AVERAGE(C12,E12),""),"") | J12: =IF(COUNT(C12,E12)=2,IF(N(G12)>0,AVERAGE(C12,E12)/G12,""),"")
A13: 8 | B13: =EDATE(Settings!$B$4,$A13-1) -> 46539 | F13: =IF(COUNT(C13,E13)=2,IF(AVERAGE(C13,E13)>0,N(D13)/AVERAGE(C13,E13),""),"") | I13: =IF(COUNT(C13,E13)=2,IF(AVERAGE(C13,E13)>0,H13/AVERAGE(C13,E13),""),"") | J13: =IF(COUNT(C13,E13)=2,IF(N(G13)>0,AVERAGE(C13,E13)/G13,""),"")
A14: 9 | B14: =EDATE(Settings!$B$4,$A14-1) -> 46569 | F14: =IF(COUNT(C14,E14)=2,IF(AVERAGE(C14,E14)>0,N(D14)/AVERAGE(C14,E14),""),"") | I14: =IF(COUNT(C14,E14)=2,IF(AVERAGE(C14,E14)>0,H14/AVERAGE(C14,E14),""),"") | J14: =IF(COUNT(C14,E14)=2,IF(N(G14)>0,AVERAGE(C14,E14)/G14,""),"")
A15: 10 | B15: =EDATE(Settings!$B$4,$A15-1) -> 46600 | F15: =IF(COUNT(C15,E15)=2,IF(AVERAGE(C15,E15)>0,N(D15)/AVERAGE(C15,E15),""),"") | I15: =IF(COUNT(C15,E15)=2,IF(AVERAGE(C15,E15)>0,H15/AVERAGE(C15,E15),""),"") | J15: =IF(COUNT(C15,E15)=2,IF(N(G15)>0,AVERAGE(C15,E15)/G15,""),"")
A16: 11 | B16: =EDATE(Settings!$B$4,$A16-1) -> 46631 | F16: =IF(COUNT(C16,E16)=2,IF(AVERAGE(C16,E16)>0,N(D16)/AVERAGE(C16,E16),""),"") | I16: =IF(COUNT(C16,E16)=2,IF(AVERAGE(C16,E16)>0,H16/AVERAGE(C16,E16),""),"") | J16: =IF(COUNT(C16,E16)=2,IF(N(G16)>0,AVERAGE(C16,E16)/G16,""),"")
A17: 12 | B17: =EDATE(Settings!$B$4,$A17-1) -> 46661 | F17: =IF(COUNT(C17,E17)=2,IF(AVERAGE(C17,E17)>0,N(D17)/AVERAGE(C17,E17),""),"") | I17: =IF(COUNT(C17,E17)=2,IF(AVERAGE(C17,E17)>0,H17/AVERAGE(C17,E17),""),"") | J17: =IF(COUNT(C17,E17)=2,IF(N(G17)>0,AVERAGE(C17,E17)/G17,""),"")

Sheet LQ6_Location
A1: LQ6: Kiosk location yield (market, park, health facility)
A2: Indicators: foot-traffic-to-registration conversion rate; monthly method uptake per site category. Responsible: Implementation partner. Weekly. One row per kiosk per week.
A3: Yellow cells (blue text) = enter data. Grey cells = formulas, do not overwrite. Row 6 holds an EXAMPLE entry: overwrite or clear it before real use.
K4: Summary by site category (cumulative)
A5: Week # | B5: Week start | C5: Kiosk / site | D5: Site category | E5: Foot traffic (tally) | F5: Registrations | G5: Method uptake | H5: Foot traffic → registration | I5: Uptake ÷ registration | K5: Site category | L5: Foot traffic | M5: Registrations | N5: Method uptake | O5: Foot traffic → registration | P5: Uptake ÷ registration
A6: 1 | B6: =IF($A6="","",Settings!$B$4+7*($A6-1)) -> 46327 | C6: K01 | D6: Market | E6: 1200 | F6: 310 | G6: 150 | H6: =IF(N(E6)>0,F6/E6,"") -> 0.25833333 | I6: =IF(N(F6)>0,G6/F6,"") -> 0.48387097 | K6: =Settings!$H$4 -> Market | L6: =SUMIFS($E$6:$E$205,$D$6:$D$205,$K6) -> 1200 | M6: =SUMIFS($F$6:$F$205,$D$6:$D$205,$K6) -> 310 | N6: =SUMIFS($G$6:$G$205,$D$6:$D$205,$K6) -> 150 | O6: =IF(L6>0,M6/L6,"") -> 0.25833333 | P6: =IF(M6>0,N6/M6,"") -> 0.48387097
B7: =IF($A7="","",Settings!$B$4+7*($A7-1)) | H7: =IF(N(E7)>0,F7/E7,"") | I7: =IF(N(F7)>0,G7/F7,"") | K7: =Settings!$H$5 -> Park | L7: =SUMIFS($E$6:$E$205,$D$6:$D$205,$K7) -> 0 | M7: =SUMIFS($F$6:$F$205,$D$6:$D$205,$K7) -> 0 | N7: =SUMIFS($G$6:$G$205,$D$6:$D$205,$K7) -> 0 | O7: =IF(L7>0,M7/L7,"") | P7: =IF(M7>0,N7/M7,"")
B8: =IF($A8="","",Settings!$B$4+7*($A8-1)) | H8: =IF(N(E8)>0,F8/E8,"") | I8: =IF(N(F8)>0,G8/F8,"") | K8: =Settings!$H$6 -> Health facility | L8: =SUMIFS($E$6:$E$205,$D$6:$D$205,$K8) -> 0 | M8: =SUMIFS($F$6:$F$205,$D$6:$D$205,$K8) -> 0 | N8: =SUMIFS($G$6:$G$205,$D$6:$D$205,$K8) -> 0 | O8: =IF(L8>0,M8/L8,"") | P8: =IF(M8>0,N8/M8,"")
B9: =IF($A9="","",Settings!$B$4+7*($A9-1)) | H9: =IF(N(E9)>0,F9/E9,"") | I9: =IF(N(F9)>0,G9/F9,"") | K9: =Settings!$H$7 -> Other | L9: =SUMIFS($E$6:$E$205,$D$6:$D$205,$K9) -> 0 | M9: =SUMIFS($F$6:$F$205,$D$6:$D$205,$K9) -> 0 | N9: =SUMIFS($G$6:$G$205,$D$6:$D$205,$K9) -> 0 | O9: =IF(L9>0,M9/L9,"") | P9: =IF(M9>0,N9/M9,"")
B10: =IF($A10="","",Settings!$B$4+7*($A10-1)) | H10: =IF(N(E10)>0,F10/E10,"") | I10: =IF(N(F10)>0,G10/F10,"")
B11: =IF($A11="","",Settings!$B$4+7*($A11-1)) | H11: =IF(N(E11)>0,F11/E11,"") | I11: =IF(N(F11)>0,G11/F11,"")
B12: =IF($A12="","",Settings!$B$4+7*($A12-1)) | H12: =IF(N(E12)>0,F12/E12,"") | I12: =IF(N(F12)>0,G12/F12,"")
B13: =IF($A13="","",Settings!$B$4+7*($A13-1)) | H13: =IF(N(E13)>0,F13/E13,"") | I13: =IF(N(F13)>0,G13/F13,"")
B14: =IF($A14="","",Settings!$B$4+7*($A14-1)) | H14: =IF(N(E14)>0,F14/E14,"") | I14: =IF(N(F14)>0,G14/F14,"")
B15: =IF($A15="","",Settings!$B$4+7*($A15-1)) | H15: =IF(N(E15)>0,F15/E15,"") | I15: =IF(N(F15)>0,G15/F15,"")
B16: =IF($A16="","",Settings!$B$4+7*($A16-1)) | H16: =IF(N(E16)>0,F16/E16,"") | I16: =IF(N(F16)>0,G16/F16,"")
B17: =IF($A17="","",Settings!$B$4+7*($A17-1)) | H17: =IF(N(E17)>0,F17/E17,"") | I17: =IF(N(F17)>0,G17/F17,"")
B18: =IF($A18="","",Settings!$B$4+7*($A18-1)) | H18: =IF(N(E18)>0,F18/E18,"") | I18: =IF(N(F18)>0,G18/F18,"")
B19: =IF($A19="","",Settings!$B$4+7*($A19-1)) | H19: =IF(N(E19)>0,F19/E19,"") | I19: =IF(N(F19)>0,G19/F19,"")
B20: =IF($A20="","",Settings!$B$4+7*($A20-1)) | H20: =IF(N(E20)>0,F20/E20,"") | I20: =IF(N(F20)>0,G20/F20,"")
B21: =IF($A21="","",Settings!$B$4+7*($A21-1)) | H21: =IF(N(E21)>0,F21/E21,"") | I21: =IF(N(F21)>0,G21/F21,"")
... B205: =IF($A205="","",Settings!$B$4+7*($A205-1)) | H205: =IF(N(E205)>0,F205/E205,"") | I205: =IF(N(F205)>0,G205/F205,"")

Sheet LQ7_Methods
A1: LQ7: Method utilization, refusal and discontinuation
A2: Indicators: method-uptake distribution (%); discontinuation rate; refusal-reason frequency (coded from digital counseling notes). Responsible: Implementation partner & kiosk providers. Monthly. One row per method per month.
A3: Yellow cells (blue text) = enter data. Grey cells = formulas, do not overwrite. Row 6 holds an EXAMPLE entry: overwrite or clear it before real use.
H4: Refusal reasons (coded from counseling notes) | L4: Summary: method utilization (cumulative)
A5: Month # | B5: Month | C5: Method | D5: Clients accepting method | E5: Clients discontinuing | F5: Discontinuation rate | H5: Month # | I5: Refusal reason | J5: Refusals (count) | L5: Method | M5: Clients accepting | N5: % of total | O5: Discontinued | P5: Discontinuation rate
A6: 1 | B6: =IF($A6="","",EDATE(Settings!$B$4,$A6-1)) -> 46327 | C6: Injectable | D6: 120 | E6: 4 | F6: =IF(N(D6)>0,E6/D6,"") -> 0.033333333 | H6: 1 | I6: Fear of side effects | J6: 18 | L6: =Settings!$E$4 -> Pill | M6: =SUMIFS($D$6:$D$105,$C$6:$C$105,$L6) -> 0 | N6: =IF($M$13>0,M6/$M$13,"") -> 0 | O6: =SUMIFS($E$6:$E$105,$C$6:$C$105,$L6) -> 0 | P6: =IF(M6>0,O6/M6,"")
B7: =IF($A7="","",EDATE(Settings!$B$4,$A7-1)) | F7: =IF(N(D7)>0,E7/D7,"") | L7: =Settings!$E$5 -> Injectable | M7: =SUMIFS($D$6:$D$105,$C$6:$C$105,$L7) -> 120 | N7: =IF($M$13>0,M7/$M$13,"") -> 1 | O7: =SUMIFS($E$6:$E$105,$C$6:$C$105,$L7) -> 4 | P7: =IF(M7>0,O7/M7,"") -> 0.033333333
B8: =IF($A8="","",EDATE(Settings!$B$4,$A8-1)) | F8: =IF(N(D8)>0,E8/D8,"") | L8: =Settings!$E$6 -> Implant | M8: =SUMIFS($D$6:$D$105,$C$6:$C$105,$L8) -> 0 | N8: =IF($M$13>0,M8/$M$13,"") -> 0 | O8: =SUMIFS($E$6:$E$105,$C$6:$C$105,$L8) -> 0 | P8: =IF(M8>0,O8/M8,"")
B9: =IF($A9="","",EDATE(Settings!$B$4,$A9-1)) | F9: =IF(N(D9)>0,E9/D9,"") | L9: =Settings!$E$7 -> IUD | M9: =SUMIFS($D$6:$D$105,$C$6:$C$105,$L9) -> 0 | N9: =IF($M$13>0,M9/$M$13,"") -> 0 | O9: =SUMIFS($E$6:$E$105,$C$6:$C$105,$L9) -> 0 | P9: =IF(M9>0,O9/M9,"")
B10: =IF($A10="","",EDATE(Settings!$B$4,$A10-1)) | F10: =IF(N(D10)>0,E10/D10,"") | L10: =Settings!$E$8 -> Condom | M10: =SUMIFS($D$6:$D$105,$C$6:$C$105,$L10) -> 0 | N10: =IF($M$13>0,M10/$M$13,"") -> 0 | O10: =SUMIFS($E$6:$E$105,$C$6:$C$105,$L10) -> 0 | P10: =IF(M10>0,O10/M10,"")
B11: =IF($A11="","",EDATE(Settings!$B$4,$A11-1)) | F11: =IF(N(D11)>0,E11/D11,"") | L11: =Settings!$E$9 -> Emergency contraception | M11: =SUMIFS($D$6:$D$105,$C$6:$C$105,$L11) -> 0 | N11: =IF($M$13>0,M11/$M$13,"") -> 0 | O11: =SUMIFS($E$6:$E$105,$C$6:$C$105,$L11) -> 0 | P11: =IF(M11>0,O11/M11,"")
B12: =IF($A12="","",EDATE(Settings!$B$4,$A12-1)) | F12: =IF(N(D12)>0,E12/D12,"") | L12: =Settings!$E$10 -> Other | M12: =SUMIFS($D$6:$D$105,$C$6:$C$105,$L12) -> 0 | N12: =IF($M$13>0,M12/$M$13,"") -> 0 | O12: =SUMIFS($E$6:$E$105,$C$6:$C$105,$L12) -> 0 | P12: =IF(M12>0,O12/M12,"")
B13: =IF($A13="","",EDATE(Settings!$B$4,$A13-1)) | F13: =IF(N(D13)>0,E13/D13,"") | L13: Total | M13: =SUM(M6:M12) -> 120 | N13: =IF(M13>0,1,"") -> 1 | O13: =SUM(O6:O12) -> 4 | P13: =IF(M13>0,O13/M13,"") -> 0.033333333
B14: =IF($A14="","",EDATE(Settings!$B$4,$A14-1)) | F14: =IF(N(D14)>0,E14/D14,"")
B15: =IF($A15="","",EDATE(Settings!$B$4,$A15-1)) | F15: =IF(N(D15)>0,E15/D15,"") | L15: Summary: refusal reasons (cumulative)
B16: =IF($A16="","",EDATE(Settings!$B$4,$A16-1)) | F16: =IF(N(D16)>0,E16/D16,"") | L16: Refusal reason | M16: Count | N16: % of refusals
B17: =IF($A17="","",EDATE(Settings!$B$4,$A17-1)) | F17: =IF(N(D17)>0,E17/D17,"") | L17: =Settings!$I$4 -> Fear of side effects | M17: =SUMIFS($J$6:$J$105,$I$6:$I$105,$L17) -> 18 | N17: =IF(SUM($M$17:$M$22)>0,M17/SUM($M$17:$M$22),"") -> 1
B18: =IF($A18="","",EDATE(Settings!$B$4,$A18-1)) | F18: =IF(N(D18)>0,E18/D18,"") | L18: =Settings!$I$5 -> Partner opposition | M18: =SUMIFS($J$6:$J$105,$I$6:$I$105,$L18) -> 0 | N18: =IF(SUM($M$17:$M$22)>0,M18/SUM($M$17:$M$22),"") -> 0
B19: =IF($A19="","",EDATE(Settings!$B$4,$A19-1)) | F19: =IF(N(D19)>0,E19/D19,"") | L19: =Settings!$I$6 -> Method not available | M19: =SUMIFS($J$6:$J$105,$I$6:$I$105,$L19) -> 0 | N19: =IF(SUM($M$17:$M$22)>0,M19/SUM($M$17:$M$22),"") -> 0
B20: =IF($A20="","",EDATE(Settings!$B$4,$A20-1)) | F20: =IF(N(D20)>0,E20/D20,"") | L20: =Settings!$I$7 -> Wants time to think | M20: =SUMIFS($J$6:$J$105,$I$6:$I$105,$L20) -> 0 | N20: =IF(SUM($M$17:$M$22)>0,M20/SUM($M$17:$M$22),"") -> 0
B21: =IF($A21="","",EDATE(Settings!$B$4,$A21-1)) | F21: =IF(N(D21)>0,E21/D21,"") | L21: =Settings!$I$8 -> Religious / cultural | M21: =SUMIFS($J$6:$J$105,$I$6:$I$105,$L21) -> 0 | N21: =IF(SUM($M$17:$M$22)>0,M21/SUM($M$17:$M$22),"") -> 0
B22: =IF($A22="","",EDATE(Settings!$B$4,$A22-1)) | F22: =IF(N(D22)>0,E22/D22,"") | L22: =Settings!$I$9 -> Other | M22: =SUMIFS($J$6:$J$105,$I$6:$I$105,$L22) -> 0 | N22: =IF(SUM($M$17:$M$22)>0,M22/SUM($M$17:$M$22),"") -> 0
B23: =IF($A23="","",EDATE(Settings!$B$4,$A23-1)) | F23: =IF(N(D23)>0,E23/D23,"")
B24: =IF($A24="","",EDATE(Settings!$B$4,$A24-1)) | F24: =IF(N(D24)>0,E24/D24,"")
B25: =IF($A25="","",EDATE(Settings!$B$4,$A25-1)) | F25: =IF(N(D25)>0,E25/D25,"")
B26: =IF($A26="","",EDATE(Settings!$B$4,$A26-1)) | F26: =IF(N(D26)>0,E26/D26,"")
B27: =IF($A27="","",EDATE(Settings!$B$4,$A27-1)) | F27: =IF(N(D27)>0,E27/D27,"")
B28: =IF($A28="","",EDATE(Settings!$B$4,$A28-1)) | F28: =IF(N(D28)>0,E28/D28,"")
B29: =IF($A29="","",EDATE(Settings!$B$4,$A29-1)) | F29: =IF(N(D29)>0,E29/D29,"")
B30: =IF($A30="","",EDATE(Settings!$B$4,$A30-1)) | F30: =IF(N(D30)>0,E30/D30,"")
B31: =IF($A31="","",EDATE(Settings!$B$4,$A31-1)) | F31: =IF(N(D31)>0,E31/D31,"")
B32: =IF($A32="","",EDATE(Settings!$B$4,$A32-1)) | F32: =IF(N(D32)>0,E32/D32,"")
B33: =IF($A33="","",EDATE(Settings!$B$4,$A33-1)) | F33: =IF(N(D33)>0,E33/D33,"")
B34: =IF($A34="","",EDATE(Settings!$B$4,$A34-1)) | F34: =IF(N(D34)>0,E34/D34,"")
... B105: =IF($A105="","",EDATE(Settings!$B$4,$A105-1)) | F105: =IF(N(D105)>0,E105/D105,"")

Sheet LQ8_Cost
A1: LQ8: Operational cost per client and per kiosk
A2: Indicators: unit cost per client served (total cost ÷ total clients); operating cost per kiosk. Platform build cost is tracked separately and EXCLUDED from unit cost. Responsible: City finance lead & project manager. Monthly. Amounts in the currency set on Settings.
A3: Yellow cells (blue text) = enter data. Grey cells = formulas, do not overwrite. Row 6 holds an EXAMPLE entry: overwrite or clear it before real use.
A5: Month # | B5: Month | C5: Staff costs | D5: Rent / utilities | E5: Commodities / supplies | F5: Other operating costs | G5: Total operating cost | H5: Platform build cost (tracked separately) | I5: Kiosks operating | J5: Clients served | K5: Unit cost per client | L5: Operating cost per kiosk
A6: 1 | B6: =EDATE(Settings!$B$4,$A6-1) -> 46327 | C6: 2400000 | D6: 600000 | E6: 1200000 | F6: 300000 | G6: =IF(COUNT(C6:F6)=0,"",SUM(C6:F6)) -> 4500000 | H6: 5000000 | I6: 4 | J6: 885 | K6: =IF(AND(ISNUMBER(G6),N(J6)>0),G6/J6,"") -> 5084.7458 | L6: =IF(AND(ISNUMBER(G6),N(I6)>0),G6/I6,"") -> 1125000
A7: 2 | B7: =EDATE(Settings!$B$4,$A7-1) -> 46357 | G7: =IF(COUNT(C7:F7)=0,"",SUM(C7:F7)) | K7: =IF(AND(ISNUMBER(G7),N(J7)>0),G7/J7,"") | L7: =IF(AND(ISNUMBER(G7),N(I7)>0),G7/I7,"")
A8: 3 | B8: =EDATE(Settings!$B$4,$A8-1) -> 46388 | G8: =IF(COUNT(C8:F8)=0,"",SUM(C8:F8)) | K8: =IF(AND(ISNUMBER(G8),N(J8)>0),G8/J8,"") | L8: =IF(AND(ISNUMBER(G8),N(I8)>0),G8/I8,"")
A9: 4 | B9: =EDATE(Settings!$B$4,$A9-1) -> 46419 | G9: =IF(COUNT(C9:F9)=0,"",SUM(C9:F9)) | K9: =IF(AND(ISNUMBER(G9),N(J9)>0),G9/J9,"") | L9: =IF(AND(ISNUMBER(G9),N(I9)>0),G9/I9,"")
A10: 5 | B10: =EDATE(Settings!$B$4,$A10-1) -> 46447 | G10: =IF(COUNT(C10:F10)=0,"",SUM(C10:F10)) | K10: =IF(AND(ISNUMBER(G10),N(J10)>0),G10/J10,"") | L10: =IF(AND(ISNUMBER(G10),N(I10)>0),G10/I10,"")
A11: 6 | B11: =EDATE(Settings!$B$4,$A11-1) -> 46478 | G11: =IF(COUNT(C11:F11)=0,"",SUM(C11:F11)) | K11: =IF(AND(ISNUMBER(G11),N(J11)>0),G11/J11,"") | L11: =IF(AND(ISNUMBER(G11),N(I11)>0),G11/I11,"")
A12: 7 | B12: =EDATE(Settings!$B$4,$A12-1) -> 46508 | G12: =IF(COUNT(C12:F12)=0,"",SUM(C12:F12)) | K12: =IF(AND(ISNUMBER(G12),N(J12)>0),G12/J12,"") | L12: =IF(AND(ISNUMBER(G12),N(I12)>0),G12/I12,"")
A13: 8 | B13: =EDATE(Settings!$B$4,$A13-1) -> 46539 | G13: =IF(COUNT(C13:F13)=0,"",SUM(C13:F13)) | K13: =IF(AND(ISNUMBER(G13),N(J13)>0),G13/J13,"") | L13: =IF(AND(ISNUMBER(G13),N(I13)>0),G13/I13,"")
A14: 9 | B14: =EDATE(Settings!$B$4,$A14-1) -> 46569 | G14: =IF(COUNT(C14:F14)=0,"",SUM(C14:F14)) | K14: =IF(AND(ISNUMBER(G14),N(J14)>0),G14/J14,"") | L14: =IF(AND(ISNUMBER(G14),N(I14)>0),G14/I14,"")
A15: 10 | B15: =EDATE(Settings!$B$4,$A15-1) -> 46600 | G15: =IF(COUNT(C15:F15)=0,"",SUM(C15:F15)) | K15: =IF(AND(ISNUMBER(G15),N(J15)>0),G15/J15,"") | L15: =IF(AND(ISNUMBER(G15),N(I15)>0),G15/I15,"")
A16: 11 | B16: =EDATE(Settings!$B$4,$A16-1) -> 46631 | G16: =IF(COUNT(C16:F16)=0,"",SUM(C16:F16)) | K16: =IF(AND(ISNUMBER(G16),N(J16)>0),G16/J16,"") | L16: =IF(AND(ISNUMBER(G16),N(I16)>0),G16/I16,"")
A17: 12 | B17: =EDATE(Settings!$B$4,$A17-1) -> 46661 | G17: =IF(COUNT(C17:F17)=0,"",SUM(C17:F17)) | K17: =IF(AND(ISNUMBER(G17),N(J17)>0),G17/J17,"") | L17: =IF(AND(ISNUMBER(G17),N(I17)>0),G17/I17,"")

Sheet LQ9_SBC
A1: LQ9: Social and Behavior Change (SBC) channel effectiveness by demographic
A2: Indicators: acquisition volume by channel; channel conversion rate by age/demographic (demographic breakdown reported quarterly for sample stability). Responsible: Implementation partner. One row per channel × age group per month.
A3: Yellow cells (blue text) = enter data. Grey cells = formulas, do not overwrite. Row 6 holds an EXAMPLE entry: overwrite or clear it before real use.
I4: Summary by channel (cumulative)
A5: Month # | B5: Month | C5: Channel | D5: Age group | E5: Clients acquired | F5: Converted to method uptake | G5: Conversion rate | I5: Channel | J5: Clients acquired | K5: Converted | L5: Conversion rate
A6: 1 | B6: =IF($A6="","",EDATE(Settings!$B$4,$A6-1)) -> 46327 | C6: Mobilizer | D6: 20-24 yrs | E6: 85 | F6: 40 | G6: =IF(N(E6)>0,F6/E6,"") -> 0.47058824 | I6: =Settings!$F$4 -> App (self-referral) | J6: =SUMIFS($E$6:$E$205,$C$6:$C$205,$I6) -> 0 | K6: =SUMIFS($F$6:$F$205,$C$6:$C$205,$I6) -> 0 | L6: =IF(J6>0,K6/J6,"")
B7: =IF($A7="","",EDATE(Settings!$B$4,$A7-1)) | G7: =IF(N(E7)>0,F7/E7,"") | I7: =Settings!$F$5 -> Mobilizer | J7: =SUMIFS($E$6:$E$205,$C$6:$C$205,$I7) -> 85 | K7: =SUMIFS($F$6:$F$205,$C$6:$C$205,$I7) -> 40 | L7: =IF(J7>0,K7/J7,"") -> 0.47058824
B8: =IF($A8="","",EDATE(Settings!$B$4,$A8-1)) | G8: =IF(N(E8)>0,F8/E8,"") | I8: =Settings!$F$6 -> Walk-in | J8: =SUMIFS($E$6:$E$205,$C$6:$C$205,$I8) -> 0 | K8: =SUMIFS($F$6:$F$205,$C$6:$C$205,$I8) -> 0 | L8: =IF(J8>0,K8/J8,"")
B9: =IF($A9="","",EDATE(Settings!$B$4,$A9-1)) | G9: =IF(N(E9)>0,F9/E9,"") | I9: =Settings!$F$7 -> Social media | J9: =SUMIFS($E$6:$E$205,$C$6:$C$205,$I9) -> 0 | K9: =SUMIFS($F$6:$F$205,$C$6:$C$205,$I9) -> 0 | L9: =IF(J9>0,K9/J9,"")
B10: =IF($A10="","",EDATE(Settings!$B$4,$A10-1)) | G10: =IF(N(E10)>0,F10/E10,"") | I10: =Settings!$F$8 -> Radio | J10: =SUMIFS($E$6:$E$205,$C$6:$C$205,$I10) -> 0 | K10: =SUMIFS($F$6:$F$205,$C$6:$C$205,$I10) -> 0 | L10: =IF(J10>0,K10/J10,"")
B11: =IF($A11="","",EDATE(Settings!$B$4,$A11-1)) | G11: =IF(N(E11)>0,F11/E11,"") | I11: =Settings!$F$9 -> Community event | J11: =SUMIFS($E$6:$E$205,$C$6:$C$205,$I11) -> 0 | K11: =SUMIFS($F$6:$F$205,$C$6:$C$205,$I11) -> 0 | L11: =IF(J11>0,K11/J11,"")
B12: =IF($A12="","",EDATE(Settings!$B$4,$A12-1)) | G12: =IF(N(E12)>0,F12/E12,"") | I12: =Settings!$F$10 -> Digital referral code | J12: =SUMIFS($E$6:$E$205,$C$6:$C$205,$I12) -> 0 | K12: =SUMIFS($F$6:$F$205,$C$6:$C$205,$I12) -> 0 | L12: =IF(J12>0,K12/J12,"")
B13: =IF($A13="","",EDATE(Settings!$B$4,$A13-1)) | G13: =IF(N(E13)>0,F13/E13,"")
B14: =IF($A14="","",EDATE(Settings!$B$4,$A14-1)) | G14: =IF(N(E14)>0,F14/E14,"") | I14: Conversion rate: channel × age group (review quarterly)
B15: =IF($A15="","",EDATE(Settings!$B$4,$A15-1)) | G15: =IF(N(E15)>0,F15/E15,"") | I15: Channel | J15: =Settings!$G$4 -> 15-19 yrs | K15: =Settings!$G$5 -> 20-24 yrs | L15: =Settings!$G$6 -> 25-34 yrs | M15: =Settings!$G$7 -> 35-49 yrs
B16: =IF($A16="","",EDATE(Settings!$B$4,$A16-1)) | G16: =IF(N(E16)>0,F16/E16,"") | I16: =Settings!$F$4 -> App (self-referral) | J16: =IFERROR(SUMIFS($F$6:$F$205,$C$6:$C$205,$I16,$D$6:$D$205,J$15)/SUMIFS($E$6:$E$205,$C$6:$C$205,$I16,$D$6:$D$205,J$15),"") | K16: =IFERROR(SUMIFS($F$6:$F$205,$C$6:$C$205,$I16,$D$6:$D$205,K$15)/SUMIFS($E$6:$E$205,$C$6:$C$205,$I16,$D$6:$D$205,K$15),"") | L16: =IFERROR(SUMIFS($F$6:$F$205,$C$6:$C$205,$I16,$D$6:$D$205,L$15)/SUMIFS($E$6:$E$205,$C$6:$C$205,$I16,$D$6:$D$205,L$15),"") | M16: =IFERROR(SUMIFS($F$6:$F$205,$C$6:$C$205,$I16,$D$6:$D$205,M$15)/SUMIFS($E$6:$E$205,$C$6:$C$205,$I16,$D$6:$D$205,M$15),"")
B17: =IF($A17="","",EDATE(Settings!$B$4,$A17-1)) | G17: =IF(N(E17)>0,F17/E17,"") | I17: =Settings!$F$5 -> Mobilizer | J17: =IFERROR(SUMIFS($F$6:$F$205,$C$6:$C$205,$I17,$D$6:$D$205,J$15)/SUMIFS($E$6:$E$205,$C$6:$C$205,$I17,$D$6:$D$205,J$15),"") | K17: =IFERROR(SUMIFS($F$6:$F$205,$C$6:$C$205,$I17,$D$6:$D$205,K$15)/SUMIFS($E$6:$E$205,$C$6:$C$205,$I17,$D$6:$D$205,K$15),"") -> 0.47058824 | L17: =IFERROR(SUMIFS($F$6:$F$205,$C$6:$C$205,$I17,$D$6:$D$205,L$15)/SUMIFS($E$6:$E$205,$C$6:$C$205,$I17,$D$6:$D$205,L$15),"") | M17: =IFERROR(SUMIFS($F$6:$F$205,$C$6:$C$205,$I17,$D$6:$D$205,M$15)/SUMIFS($E$6:$E$205,$C$6:$C$205,$I17,$D$6:$D$205,M$15),"")
B18: =IF($A18="","",EDATE(Settings!$B$4,$A18-1)) | G18: =IF(N(E18)>0,F18/E18,"") | I18: =Settings!$F$6 -> Walk-in | J18: =IFERROR(SUMIFS($F$6:$F$205,$C$6:$C$205,$I18,$D$6:$D$205,J$15)/SUMIFS($E$6:$E$205,$C$6:$C$205,$I18,$D$6:$D$205,J$15),"") | K18: =IFERROR(SUMIFS($F$6:$F$205,$C$6:$C$205,$I18,$D$6:$D$205,K$15)/SUMIFS($E$6:$E$205,$C$6:$C$205,$I18,$D$6:$D$205,K$15),"") | L18: =IFERROR(SUMIFS($F$6:$F$205,$C$6:$C$205,$I18,$D$6:$D$205,L$15)/SUMIFS($E$6:$E$205,$C$6:$C$205,$I18,$D$6:$D$205,L$15),"") | M18: =IFERROR(SUMIFS($F$6:$F$205,$C$6:$C$205,$I18,$D$6:$D$205,M$15)/SUMIFS($E$6:$E$205,$C$6:$C$205,$I18,$D$6:$D$205,M$15),"")
B19: =IF($A19="","",EDATE(Settings!$B$4,$A19-1)) | G19: =IF(N(E19)>0,F19/E19,"") | I19: =Settings!$F$7 -> Social media | J19: =IFERROR(SUMIFS($F$6:$F$205,$C$6:$C$205,$I19,$D$6:$D$205,J$15)/SUMIFS($E$6:$E$205,$C$6:$C$205,$I19,$D$6:$D$205,J$15),"") | K19: =IFERROR(SUMIFS($F$6:$F$205,$C$6:$C$205,$I19,$D$6:$D$205,K$15)/SUMIFS($E$6:$E$205,$C$6:$C$205,$I19,$D$6:$D$205,K$15),"") | L19: =IFERROR(SUMIFS($F$6:$F$205,$C$6:$C$205,$I19,$D$6:$D$205,L$15)/SUMIFS($E$6:$E$205,$C$6:$C$205,$I19,$D$6:$D$205,L$15),"") | M19: =IFERROR(SUMIFS($F$6:$F$205,$C$6:$C$205,$I19,$D$6:$D$205,M$15)/SUMIFS($E$6:$E$205,$C$6:$C$205,$I19,$D$6:$D$205,M$15),"")
B20: =IF($A20="","",EDATE(Settings!$B$4,$A20-1)) | G20: =IF(N(E20)>0,F20/E20,"") | I20: =Settings!$F$8 -> Radio | J20: =IFERROR(SUMIFS($F$6:$F$205,$C$6:$C$205,$I20,$D$6:$D$205,J$15)/SUMIFS($E$6:$E$205,$C$6:$C$205,$I20,$D$6:$D$205,J$15),"") | K20: =IFERROR(SUMIFS($F$6:$F$205,$C$6:$C$205,$I20,$D$6:$D$205,K$15)/SUMIFS($E$6:$E$205,$C$6:$C$205,$I20,$D$6:$D$205,K$15),"") | L20: =IFERROR(SUMIFS($F$6:$F$205,$C$6:$C$205,$I20,$D$6:$D$205,L$15)/SUMIFS($E$6:$E$205,$C$6:$C$205,$I20,$D$6:$D$205,L$15),"") | M20: =IFERROR(SUMIFS($F$6:$F$205,$C$6:$C$205,$I20,$D$6:$D$205,M$15)/SUMIFS($E$6:$E$205,$C$6:$C$205,$I20,$D$6:$D$205,M$15),"")
B21: =IF($A21="","",EDATE(Settings!$B$4,$A21-1)) | G21: =IF(N(E21)>0,F21/E21,"") | I21: =Settings!$F$9 -> Community event | J21: =IFERROR(SUMIFS($F$6:$F$205,$C$6:$C$205,$I21,$D$6:$D$205,J$15)/SUMIFS($E$6:$E$205,$C$6:$C$205,$I21,$D$6:$D$205,J$15),"") | K21: =IFERROR(SUMIFS($F$6:$F$205,$C$6:$C$205,$I21,$D$6:$D$205,K$15)/SUMIFS($E$6:$E$205,$C$6:$C$205,$I21,$D$6:$D$205,K$15),"") | L21: =IFERROR(SUMIFS($F$6:$F$205,$C$6:$C$205,$I21,$D$6:$D$205,L$15)/SUMIFS($E$6:$E$205,$C$6:$C$205,$I21,$D$6:$D$205,L$15),"") | M21: =IFERROR(SUMIFS($F$6:$F$205,$C$6:$C$205,$I21,$D$6:$D$205,M$15)/SUMIFS($E$6:$E$205,$C$6:$C$205,$I21,$D$6:$D$205,M$15),"")
B22: =IF($A22="","",EDATE(Settings!$B$4,$A22-1)) | G22: =IF(N(E22)>0,F22/E22,"") | I22: =Settings!$F$10 -> Digital referral code | J22: =IFERROR(SUMIFS($F$6:$F$205,$C$6:$C$205,$I22,$D$6:$D$205,J$15)/SUMIFS($E$6:$E$205,$C$6:$C$205,$I22,$D$6:$D$205,J$15),"") | K22: =IFERROR(SUMIFS($F$6:$F$205,$C$6:$C$205,$I22,$D$6:$D$205,K$15)/SUMIFS($E$6:$E$205,$C$6:$C$205,$I22,$D$6:$D$205,K$15),"") | L22: =IFERROR(SUMIFS($F$6:$F$205,$C$6:$C$205,$I22,$D$6:$D$205,L$15)/SUMIFS($E$6:$E$205,$C$6:$C$205,$I22,$D$6:$D$205,L$15),"") | M22: =IFERROR(SUMIFS($F$6:$F$205,$C$6:$C$205,$I22,$D$6:$D$205,M$15)/SUMIFS($E$6:$E$205,$C$6:$C$205,$I22,$D$6:$D$205,M$15),"")
B23: =IF($A23="","",EDATE(Settings!$B$4,$A23-1)) | G23: =IF(N(E23)>0,F23/E23,"")
B24: =IF($A24="","",EDATE(Settings!$B$4,$A24-1)) | G24: =IF(N(E24)>0,F24/E24,"")
B25: =IF($A25="","",EDATE(Settings!$B$4,$A25-1)) | G25: =IF(N(E25)>0,F25/E25,"")
B26: =IF($A26="","",EDATE(Settings!$B$4,$A26-1)) | G26: =IF(N(E26)>0,F26/E26,"")
B27: =IF($A27="","",EDATE(Settings!$B$4,$A27-1)) | G27: =IF(N(E27)>0,F27/E27,"")
B28: =IF($A28="","",EDATE(Settings!$B$4,$A28-1)) | G28: =IF(N(E28)>0,F28/E28,"")
B29: =IF($A29="","",EDATE(Settings!$B$4,$A29-1)) | G29: =IF(N(E29)>0,F29/E29,"")
B30: =IF($A30="","",EDATE(Settings!$B$4,$A30-1)) | G30: =IF(N(E30)>0,F30/E30,"")
B31: =IF($A31="","",EDATE(Settings!$B$4,$A31-1)) | G31: =IF(N(E31)>0,F31/E31,"")
B32: =IF($A32="","",EDATE(Settings!$B$4,$A32-1)) | G32: =IF(N(E32)>0,F32/E32,"")
B33: =IF($A33="","",EDATE(Settings!$B$4,$A33-1)) | G33: =IF(N(E33)>0,F33/E33,"")
B34: =IF($A34="","",EDATE(Settings!$B$4,$A34-1)) | G34: =IF(N(E34)>0,F34/E34,"")
... B205: =IF($A205="","",EDATE(Settings!$B$4,$A205-1)) | G205: =IF(N(E205)>0,F205/E205,"")

Sheet LQ10_DHIS2
A1: LQ10: DHIS2 / government data integration
A2: Indicators: data-sync success rate (target ≥95%); reporting latency (target <48h); official usability rating (target ≥4/5). Responsible: Technical / M&E lead. Monthly. Starts at mid-pilot review (leave earlier months blank).
A3: Yellow cells (blue text) = enter data. Grey cells = formulas, do not overwrite. Row 6 holds an EXAMPLE entry: overwrite or clear it before real use.
A5: Month # | B5: Month | C5: Records due to sync | D5: Records successfully synced | E5: Sync success rate | F5: Avg reporting latency (hours) | G5: Avg official usability rating (1-5) | H5: Official raters | I5: Sync target met? | J5: Latency target met? | K5: Usability target met?
A6: 1 | B6: =EDATE(Settings!$B$4,$A6-1) -> 46327 | C6: 1500 | D6: 1410 | E6: =IF(N(C6)>0,D6/C6,"") -> 0.94 | F6: 36 | G6: 4.2 | H6: 5 | I6: =IF(E6="","",IF(E6>=Settings!$B$13,"Yes","No")) -> No | J6: =IF(F6="","",IF(F6<Settings!$B$14,"Yes","No")) -> Yes | K6: =IF(G6="","",IF(G6>=Settings!$B$15,"Yes","No")) -> Yes
A7: 2 | B7: =EDATE(Settings!$B$4,$A7-1) -> 46357 | E7: =IF(N(C7)>0,D7/C7,"") | I7: =IF(E7="","",IF(E7>=Settings!$B$13,"Yes","No")) | J7: =IF(F7="","",IF(F7<Settings!$B$14,"Yes","No")) | K7: =IF(G7="","",IF(G7>=Settings!$B$15,"Yes","No"))
A8: 3 | B8: =EDATE(Settings!$B$4,$A8-1) -> 46388 | E8: =IF(N(C8)>0,D8/C8,"") | I8: =IF(E8="","",IF(E8>=Settings!$B$13,"Yes","No")) | J8: =IF(F8="","",IF(F8<Settings!$B$14,"Yes","No")) | K8: =IF(G8="","",IF(G8>=Settings!$B$15,"Yes","No"))
A9: 4 | B9: =EDATE(Settings!$B$4,$A9-1) -> 46419 | E9: =IF(N(C9)>0,D9/C9,"") | I9: =IF(E9="","",IF(E9>=Settings!$B$13,"Yes","No")) | J9: =IF(F9="","",IF(F9<Settings!$B$14,"Yes","No")) | K9: =IF(G9="","",IF(G9>=Settings!$B$15,"Yes","No"))
A10: 5 | B10: =EDATE(Settings!$B$4,$A10-1) -> 46447 | E10: =IF(N(C10)>0,D10/C10,"") | I10: =IF(E10="","",IF(E10>=Settings!$B$13,"Yes","No")) | J10: =IF(F10="","",IF(F10<Settings!$B$14,"Yes","No")) | K10: =IF(G10="","",IF(G10>=Settings!$B$15,"Yes","No"))
A11: 6 | B11: =EDATE(Settings!$B$4,$A11-1) -> 46478 | E11: =IF(N(C11)>0,D11/C11,"") | I11: =IF(E11="","",IF(E11>=Settings!$B$13,"Yes","No")) | J11: =IF(F11="","",IF(F11<Settings!$B$14,"Yes","No")) | K11: =IF(G11="","",IF(G11>=Settings!$B$15,"Yes","No"))
A12: 7 | B12: =EDATE(Settings!$B$4,$A12-1) -> 46508 | E12: =IF(N(C12)>0,D12/C12,"") | I12: =IF(E12="","",IF(E12>=Settings!$B$13,"Yes","No")) | J12: =IF(F12="","",IF(F12<Settings!$B$14,"Yes","No")) | K12: =IF(G12="","",IF(G12>=Settings!$B$15,"Yes","No"))
A13: 8 | B13: =EDATE(Settings!$B$4,$A13-1) -> 46539 | E13: =IF(N(C13)>0,D13/C13,"") | I13: =IF(E13="","",IF(E13>=Settings!$B$13,"Yes","No")) | J13: =IF(F13="","",IF(F13<Settings!$B$14,"Yes","No")) | K13: =IF(G13="","",IF(G13>=Settings!$B$15,"Yes","No"))
A14: 9 | B14: =EDATE(Settings!$B$4,$A14-1) -> 46569 | E14: =IF(N(C14)>0,D14/C14,"") | I14: =IF(E14="","",IF(E14>=Settings!$B$13,"Yes","No")) | J14: =IF(F14="","",IF(F14<Settings!$B$14,"Yes","No")) | K14: =IF(G14="","",IF(G14>=Settings!$B$15,"Yes","No"))
A15: 10 | B15: =EDATE(Settings!$B$4,$A15-1) -> 46600 | E15: =IF(N(C15)>0,D15/C15,"") | I15: =IF(E15="","",IF(E15>=Settings!$B$13,"Yes","No")) | J15: =IF(F15="","",IF(F15<Settings!$B$14,"Yes","No")) | K15: =IF(G15="","",IF(G15>=Settings!$B$15,"Yes","No"))
A16: 11 | B16: =EDATE(Settings!$B$4,$A16-1) -> 46631 | E16: =IF(N(C16)>0,D16/C16,"") | I16: =IF(E16="","",IF(E16>=Settings!$B$13,"Yes","No")) | J16: =IF(F16="","",IF(F16<Settings!$B$14,"Yes","No")) | K16: =IF(G16="","",IF(G16>=Settings!$B$15,"Yes","No"))
A17: 12 | B17: =EDATE(Settings!$B$4,$A17-1) -> 46661 | E17: =IF(N(C17)>0,D17/C17,"") | I17: =IF(E17="","",IF(E17>=Settings!$B$13,"Yes","No")) | J17: =IF(F17="","",IF(F17<Settings!$B$14,"Yes","No")) | K17: =IF(G17="","",IF(G17>=Settings!$B$15,"Yes","No"))

Sheet LQ11_Sustain
A1: LQ11: Stakeholder ownership and sustainability (qualitative / milestone tracking)
A2: Indicators: co-financing milestone achievement ($); policy-commitment adoption status. Sources: KIIs conducted and coded by the Technical/M&E lead (independent of City project leadership); digitally recorded policy meeting minutes. Quarterly.
A3: Yellow cells (blue text) = enter data. Grey = formulas. The first row of each table is an EXAMPLE: overwrite or clear it before real use.
A4: A. Co-financing milestones | I4: Summary
A5: Milestone | B5: Funder / partner | C5: Due date | D5: Target ($) | E5: Achieved ($) | F5: % achieved | G5: Status
A6: State co-financing tranche 1 | B6: Edo State Government | C6: 46477 | D6: 50000 | E6: 20000 | F6: =IF(N(D6)>0,E6/D6,"") -> 0.4 | G6: In progress | I6: Total co-financing target ($) | J6: =SUM(D6:D17) -> 50000
F7: =IF(N(D7)>0,E7/D7,"") | I7: Total co-financing achieved ($) | J7: =SUM(E6:E17) -> 20000
F8: =IF(N(D8)>0,E8/D8,"") | I8: % of co-financing achieved | J8: =IF(J6>0,J7/J6,"") -> 0.4
F9: =IF(N(D9)>0,E9/D9,"") | I9: Milestones achieved (count) | J9: =COUNTIF(G6:G17,"Achieved") -> 0
F10: =IF(N(D10)>0,E10/D10,"") | I10: Milestones missed (count) | J10: =COUNTIF(G6:G17,"Missed") -> 0
F11: =IF(N(D11)>0,E11/D11,"") | I11: Policy commitments adopted (Achieved) | J11: =COUNTIF(D22:D33,"Achieved") -> 0
F12: =IF(N(D12)>0,E12/D12,"") | I12: Policy commitments in progress | J12: =COUNTIF(D22:D33,"In progress") -> 1
F13: =IF(N(D13)>0,E13/D13,"") | I13: KII findings coded as enablers | J13: =COUNTIF(E38:E77,"Enabler") -> 1
F14: =IF(N(D14)>0,E14/D14,"") | I14: KII findings coded as barriers | J14: =COUNTIF(E38:E77,"Barrier") -> 0
F15: =IF(N(D15)>0,E15/D15,"")
F16: =IF(N(D16)>0,E16/D16,"")
F17: =IF(N(D17)>0,E17/D17,"")
A20: B. Policy commitments
A21: Policy commitment | B21: Government body | C21: Date secured / due | D21: Status
A22: MoU on DHIS2 data sharing | B22: State Ministry of Health | C22: 46568 | D22: In progress
A36: C. Key informant interview (KII) log: coded by Technical / M&E lead
A37: Key finding | B37: Stakeholder type | C37: Interview date | D37: Coded theme | E37: Enabler / barrier | F37: Interviewer (independent)
A38: Ministry committed to a 2027 budget line for kiosks | B38: State MoH official | C38: 46461 | D38: Government ownership | E38: Enabler | F38: M&E consultant

Sheet Register
A1: Indicator register (from the Data Strategy Table, parts 1-4, and the Indicator Design & Alignment Check)
A2: Reference only. Each row points to the template tab where the data is entered.
A4: # | B4: Learning question | C4: Indicator(s) | D4: Data collection source | E4: New / existing? | F4: Responsible | G4: Frequency | H4: Start date | I4: TOC level | J4: Quant / Qual | K4: Feeds headline indicator? | L4: Template tab
A5: H | B5: HEADLINE: Does the delivery chain get clients a method? | C5: Monthly Contraceptive Method Uptake Conversion Rate (%) = unique clients receiving a method ÷ unique clients engaged via App / Mobilizer / Walk-in × 100 | D5: App/CRM analytics (engagement); kiosk/PHC registers and inventory logs (uptake) | E5: Existing instruments | F5: Implementation partner | G5: Monthly | H5: At pilot launch | I5: Outcome | J5: Quantitative | K5: n/a | L5: Headline
A6: 1 | B6: What drives uptake of contraceptives and what are the barriers? What creates a good experience for women using the service? | C6: Client satisfaction score (post-visit, 1-5); barrier-reporting rate (% exit surveys citing ≥1 barrier); provider counseling-quality score (digital observation rubric) | D6: In-app post-service feedback form; digital supervisor observation checklist on kiosk/PHC tablet; CONTRAconnect service-delivery logs | E6: New | F6: City team & Implementation partner | G6: Monthly | H6: At pilot launch | I6: Early outcome | J6: Mixed | K6: No | L6: LQ1_Experience
A7: 2 | B7: At which points in the client journey do most drop-offs occur? | C7: Stage-by-stage conversion/drop-off rate (app engagement → registration → kiosk/PHC referral → method uptake) under one persistent digital client ID | D7: CONTRAconnect app and CRM analytics linked to kiosk-tablet check-ins by client ID; single digital system | E7: Existing (app/CRM) & New (funnel-stage reporting) | F7: Implementation partner | G7: Weekly | H7: At pilot launch | I7: Output | J7: Quantitative | K7: Yes | L7: LQ2_Funnel
A8: 3 | B8: How do we determine if users are satisfied? | C8: Net Promoter Score (monthly); client ambassadors (unique digital referral code used ≥2 times in a month, reviewed quarterly) | D8: In-app satisfaction survey; CRM digital referral-code tracking | E8: New | F8: City team | G8: Monthly (NPS) / Quarterly (ambassadors) | H8: 1 month post-launch | I8: Early outcome | J8: Mixed | K8: No | L8: LQ3_Satisfaction
